<?xml version="1.0"?>
<robot name="LRMate_IKFast_Optimized">

  <link name="base">
    <inertial>
      <origin xyz="0.0000000 0.0000000 0.0000000" rpy="0.0000000 0.0000000 0.0000000"/>
      <mass value="0.1"/>
      <inertia ixx="0.0" ixy="0.0" ixz="0.0" iyy="0.0" iyz="0.0" izz="0.0" />
    </inertial>
  </link>

  <joint name="joint_1" type="revolute">
    <origin xyz="0.0000000 0.0000000 0.3300000" rpy="0.0000000 0.0000000 0.0000000"/>
    <parent link="base"/>
    <child link="link_1"/>
    <axis xyz="0 0 1"/>
    <limit effort="224.147" lower="-3.14159" upper="3.14159" velocity="0.87266"/>
  </joint>

  <link name="link_1">
    <inertial>
      <origin xyz="0.0185900 0.0033700 -0.0770900" rpy="-1.5707963 0.0000000 0.0000000"/>
      <mass value="2.3985"/>
      <inertia ixx="0.02332" ixy="0.0" ixz="0.0" iyy="0.01938" iyz="0.0" izz="0.01391" />
    </inertial>
  </link>

  <joint name="joint_2" type="revolute">
    <origin xyz="0.0500000 0.0000000 0.0000000" rpy="-1.5707963 0.0000000 0.0000000"/>
    <parent link="link_1"/>
    <child link="link_2"/>
    <axis xyz="0 0 1"/>
    <limit effort="236.676" lower="-3.14159" upper="3.14159" velocity="0.87266"/>
  </joint>

  <link name="link_2">
    <inertial>
      <origin xyz="-0.0071100 -0.1326100 0.0247800" rpy="3.1415927 0.0000000 -1.5707963"/>
      <mass value="7.8019"/>
      <inertia ixx="0.03290" ixy="0.0" ixz="0.0" iyy="0.20704" iyz="0.0" izz="0.18840" />
    </inertial>
  </link>

  <joint name="joint_3" type="revolute">
    <origin xyz="0.0000000 -0.4400000 0.0000000" rpy="3.1415927 0.0000000 -1.5707963"/>
    <parent link="link_2"/>
    <child link="link_3"/>
    <axis xyz="0 0 1"/>
    <limit effort="94.924" lower="-3.14159" upper="3.14159" velocity="0.87266"/>
  </joint>

  <link name="link_3">
    <inertial>
      <origin xyz="0.0057900 -0.0059100 -0.0207300" rpy="-1.5707963 0.0000000 0.0000000"/>
      <mass value="2.9847"/>
      <inertia ixx="0.00810" ixy="0.0" ixz="0.0" iyy="0.00687" iyz="0.0" izz="0.00798" />
    </inertial>
  </link>

  <joint name="joint_4" type="revolute">
    <origin xyz="0.0350000 0.0000000 0.0000000" rpy="-1.5707963 -0.52359877 -0.0000000"/>
    <parent link="link_3"/>
    <child link="link_4"/>
    <axis xyz="0 0 1"/>
    <limit effort="23.899" lower="-3.14159" upper="3.14159" velocity="0.87266"/>
  </joint>

  <link name="link_4">
    <inertial>
      <origin xyz="-0.0002500 0.0028200 -0.2060600" rpy="1.5707963 0.0000000 0.0000000"/>
      <mass value="4.1442"/>
      <inertia ixx="0.05291" ixy="0.0" ixz="0.0" iyy="0.00570" iyz="0.0" izz="0.05315" />
    </inertial>
  </link>

  <joint name="joint_5" type="revolute">
    <origin xyz="0.0000000 0.0000000 -0.4200000" rpy="1.5707963 0.52359877 0.0000000"/>
    <parent link="link_4"/>
    <child link="link_5"/>
    <axis xyz="0 0 1"/>
    <limit effort="13.817" lower="-3.14159" upper="3.14159" velocity="0.87266"/>
  </joint>

  <link name="link_5">
    <inertial>
      <origin xyz="0.0000500 -0.0273800 -0.0044400" rpy="-1.5707963 0.0000000 0.0000000"/>
      <mass value="1.7004"/>
      <inertia ixx="0.00248" ixy="0.0" ixz="0.0" iyy="0.00244" iyz="0.0" izz="0.00120" />
    </inertial>
  </link>

  <joint name="joint_6" type="revolute">
    <origin xyz="0.0000000 0.0000000 0.0000000" rpy="-1.5707963 0.0000000 -0.0000000"/>
    <parent link="link_5"/>
    <child link="link_6"/>
    <axis xyz="0 0 1"/>
    <limit effort="6.861" lower="-3.14159" upper="3.14159" velocity="0.87266"/>
  </joint>

  <link name="link_6">
    <inertial>
      <origin xyz="-0.0001200 0.0000000 -0.0705300" rpy="3.1415927 0.0000000 0.0000000"/>
      <mass value="0.1700"/>
      <inertia ixx="0.00003" ixy="0.0" ixz="0.0" iyy="0.00003" iyz="0.0" izz="0.00005" />
    </inertial>
  </link>

  <joint name="joint_7" type="fixed">
    <origin xyz="0.0000000 0.0000000 -0.0420000" rpy="1.5707963 0.0000000 1.5707963" />
    <parent link="link_6" />
    <child link="wrist" />
  </joint>

  <link name="wrist"/>

</robot>